Sat Nov 27 16:25:47 2021

Traceback (most recent call last):
  File "/opt/virtualenvs/python3/lib/python3.8/site-packages/dislash/application_commands/slash_client.py", line 1275, in _on_slash_command
    await app_command.invoke(inter)
  File "/opt/virtualenvs/python3/lib/python3.8/site-packages/dislash/application_commands/slash_core.py", line 362, in invoke
    raise err
  File "/opt/virtualenvs/python3/lib/python3.8/site-packages/dislash/application_commands/slash_core.py", line 358, in invoke
    await self._maybe_cog_call(self._cog, interaction, interaction.data)
  File "/opt/virtualenvs/python3/lib/python3.8/site-packages/dislash/application_commands/slash_core.py", line 112, in _maybe_cog_call
    return await self(cog, inter, **kwargs)
  File "/opt/virtualenvs/python3/lib/python3.8/site-packages/dislash/application_commands/core.py", line 72, in __call__
    return await self.func(*args, **kwargs)
  File "/home/runner/TheDiscordMathProblemBot/cogs/misc_commands_cog.py", line 77, in list_trusted_users
    await inter.reply("There are no trusted users.")
  File "/opt/virtualenvs/python3/lib/python3.8/site-packages/dislash/interactions/interaction.py", line 227, in reply
    return await self.channel.send(**send_kwargs)  # type: ignore
AttributeError: 'NoneType' object has no attribute 'send'


Sat Nov 27 16:25:47 2021

Traceback (most recent call last):
  File "/opt/virtualenvs/python3/lib/python3.8/site-packages/nextcord/client.py", line 351, in _run_event
    await coro(*args, **kwargs)
  File "main.py", line 244, in on_slash_command_error
    await inter.reply(embed = embed)
  File "/opt/virtualenvs/python3/lib/python3.8/site-packages/dislash/interactions/interaction.py", line 227, in reply
    return await self.channel.send(**send_kwargs)  # type: ignore
AttributeError: 'NoneType' object has no attribute 'send'


Sat Nov 27 16:26:16 2021

Traceback (most recent call last):
  File "/opt/virtualenvs/python3/lib/python3.8/site-packages/dislash/application_commands/slash_client.py", line 1275, in _on_slash_command
    await app_command.invoke(inter)
  File "/opt/virtualenvs/python3/lib/python3.8/site-packages/dislash/application_commands/slash_core.py", line 362, in invoke
    raise err
  File "/opt/virtualenvs/python3/lib/python3.8/site-packages/dislash/application_commands/slash_core.py", line 358, in invoke
    await self._maybe_cog_call(self._cog, interaction, interaction.data)
  File "/opt/virtualenvs/python3/lib/python3.8/site-packages/dislash/application_commands/slash_core.py", line 112, in _maybe_cog_call
    return await self(cog, inter, **kwargs)
  File "/opt/virtualenvs/python3/lib/python3.8/site-packages/dislash/application_commands/core.py", line 72, in __call__
    return await self.func(*args, **kwargs)
  File "/home/runner/TheDiscordMathProblemBot/cogs/misc_commands_cog.py", line 97, in ping
    embed=SuccessEmbed(f"Pong! My latency is {round(bot.latency*1000)}ms."),
NameError: name 'bot' is not defined


Sat Nov 27 16:31:14 2021

Traceback (most recent call last):
  File "/opt/virtualenvs/python3/lib/python3.8/site-packages/dislash/application_commands/slash_client.py", line 1275, in _on_slash_command
    await app_command.invoke(inter)
  File "/opt/virtualenvs/python3/lib/python3.8/site-packages/dislash/application_commands/slash_core.py", line 362, in invoke
    raise err
  File "/opt/virtualenvs/python3/lib/python3.8/site-packages/dislash/application_commands/slash_core.py", line 358, in invoke
    await self._maybe_cog_call(self._cog, interaction, interaction.data)
  File "/opt/virtualenvs/python3/lib/python3.8/site-packages/dislash/application_commands/slash_core.py", line 112, in _maybe_cog_call
    return await self(cog, inter, **kwargs)
  File "/opt/virtualenvs/python3/lib/python3.8/site-packages/dislash/application_commands/core.py", line 72, in __call__
    return await self.func(*args, **kwargs)
  File "/home/runner/TheDiscordMathProblemBot/cogs/misc_commands_cog.py", line 80, in list_trusted_users
    await inter.reply("There are no trusted users.")
  File "/opt/virtualenvs/python3/lib/python3.8/site-packages/dislash/interactions/interaction.py", line 227, in reply
    return await self.channel.send(**send_kwargs)  # type: ignore
AttributeError: 'NoneType' object has no attribute 'send'


Sat Nov 27 16:31:14 2021

Traceback (most recent call last):
  File "/opt/virtualenvs/python3/lib/python3.8/site-packages/nextcord/client.py", line 351, in _run_event
    await coro(*args, **kwargs)
  File "main.py", line 240, in on_slash_command_error
    await inter.reply(embed=embed)
  File "/opt/virtualenvs/python3/lib/python3.8/site-packages/dislash/interactions/interaction.py", line 227, in reply
    return await self.channel.send(**send_kwargs)  # type: ignore
AttributeError: 'NoneType' object has no attribute 'send'


