Sun Nov 28 17:42:15 2021

Traceback (most recent call last):
  File "/opt/virtualenvs/python3/lib/python3.8/site-packages/dislash/application_commands/slash_client.py", line 1275, in _on_slash_command
    await app_command.invoke(inter)
  File "/opt/virtualenvs/python3/lib/python3.8/site-packages/dislash/application_commands/slash_core.py", line 362, in invoke
    raise err
  File "/opt/virtualenvs/python3/lib/python3.8/site-packages/dislash/application_commands/slash_core.py", line 358, in invoke
    await self._maybe_cog_call(self._cog, interaction, interaction.data)
  File "/opt/virtualenvs/python3/lib/python3.8/site-packages/dislash/application_commands/slash_core.py", line 112, in _maybe_cog_call
    return await self(cog, inter, **kwargs)
  File "/opt/virtualenvs/python3/lib/python3.8/site-packages/dislash/application_commands/core.py", line 72, in __call__
    return await self.func(*args, **kwargs)
TypeError: github_repo() takes 1 positional argument but 2 were given


Sun Nov 28 17:44:25 2021

Traceback (most recent call last):
  File "/opt/virtualenvs/python3/lib/python3.8/site-packages/dislash/application_commands/slash_client.py", line 1275, in _on_slash_command
    await app_command.invoke(inter)
  File "/opt/virtualenvs/python3/lib/python3.8/site-packages/dislash/application_commands/slash_core.py", line 362, in invoke
    raise err
  File "/opt/virtualenvs/python3/lib/python3.8/site-packages/dislash/application_commands/slash_core.py", line 358, in invoke
    await self._maybe_cog_call(self._cog, interaction, interaction.data)
  File "/opt/virtualenvs/python3/lib/python3.8/site-packages/dislash/application_commands/slash_core.py", line 112, in _maybe_cog_call
    return await self(cog, inter, **kwargs)
  File "/opt/virtualenvs/python3/lib/python3.8/site-packages/dislash/application_commands/core.py", line 72, in __call__
    return await self.func(*args, **kwargs)
  File "/home/runner/TheDiscordMathProblemBot/cogs/developer_commands.py", line 233, in debug
    ] = self.bot.main_cache.max_guild_problems  # the problem limit
AttributeError: 'Bot' object has no attribute 'main_cache'


Sun Nov 28 17:44:43 2021

Traceback (most recent call last):
  File "/opt/virtualenvs/python3/lib/python3.8/site-packages/dislash/application_commands/slash_client.py", line 1275, in _on_slash_command
    await app_command.invoke(inter)
  File "/opt/virtualenvs/python3/lib/python3.8/site-packages/dislash/application_commands/slash_core.py", line 362, in invoke
    raise err
  File "/opt/virtualenvs/python3/lib/python3.8/site-packages/dislash/application_commands/slash_core.py", line 358, in invoke
    await self._maybe_cog_call(self._cog, interaction, interaction.data)
  File "/opt/virtualenvs/python3/lib/python3.8/site-packages/dislash/application_commands/slash_core.py", line 112, in _maybe_cog_call
    return await self(cog, inter, **kwargs)
  File "/opt/virtualenvs/python3/lib/python3.8/site-packages/dislash/application_commands/core.py", line 72, in __call__
    return await self.func(*args, **kwargs)
  File "/home/runner/TheDiscordMathProblemBot/cogs/developer_commands.py", line 233, in debug
    ] = self.bot.main_cache.max_guild_problems  # the problem limit
AttributeError: 'Bot' object has no attribute 'main_cache'


Sun Nov 28 17:47:48 2021

Traceback (most recent call last):
  File "/opt/virtualenvs/python3/lib/python3.8/site-packages/dislash/application_commands/slash_client.py", line 1275, in _on_slash_command
    await app_command.invoke(inter)
  File "/opt/virtualenvs/python3/lib/python3.8/site-packages/dislash/application_commands/slash_core.py", line 362, in invoke
    raise err
  File "/opt/virtualenvs/python3/lib/python3.8/site-packages/dislash/application_commands/slash_core.py", line 358, in invoke
    await self._maybe_cog_call(self._cog, interaction, interaction.data)
  File "/opt/virtualenvs/python3/lib/python3.8/site-packages/dislash/application_commands/slash_core.py", line 112, in _maybe_cog_call
    return await self(cog, inter, **kwargs)
  File "/opt/virtualenvs/python3/lib/python3.8/site-packages/dislash/application_commands/core.py", line 72, in __call__
    return await self.func(*args, **kwargs)
  File "/home/runner/TheDiscordMathProblemBot/cogs/developer_commands.py", line 233, in debug
    ] = self.bot.main_cache.max_guild_problems  # the problem limit
AttributeError: 'Bot' object has no attribute 'main_cache'


Sun Nov 28 17:52:21 2021

Traceback (most recent call last):
  File "/opt/virtualenvs/python3/lib/python3.8/site-packages/dislash/application_commands/slash_client.py", line 1275, in _on_slash_command
    await app_command.invoke(inter)
  File "/opt/virtualenvs/python3/lib/python3.8/site-packages/dislash/application_commands/slash_core.py", line 362, in invoke
    raise err
  File "/opt/virtualenvs/python3/lib/python3.8/site-packages/dislash/application_commands/slash_core.py", line 358, in invoke
    await self._maybe_cog_call(self._cog, interaction, interaction.data)
  File "/opt/virtualenvs/python3/lib/python3.8/site-packages/dislash/application_commands/slash_core.py", line 112, in _maybe_cog_call
    return await self(cog, inter, **kwargs)
  File "/opt/virtualenvs/python3/lib/python3.8/site-packages/dislash/application_commands/core.py", line 72, in __call__
    return await self.func(*args, **kwargs)
  File "/home/runner/TheDiscordMathProblemBot/cogs/developer_commands.py", line 236, in debug
    if len(self.bot.cache.get_guild_problems(guild))
TypeError: object of type 'coroutine' has no len()


