Wed Nov 24 02:51:26 2021

Traceback (most recent call last):
  File "/opt/virtualenvs/python3/lib/python3.8/site-packages/dislash/application_commands/slash_client.py", line 1275, in _on_slash_command
    await app_command.invoke(inter)
  File "/opt/virtualenvs/python3/lib/python3.8/site-packages/dislash/application_commands/slash_core.py", line 362, in invoke
    raise err
  File "/opt/virtualenvs/python3/lib/python3.8/site-packages/dislash/application_commands/slash_core.py", line 358, in invoke
    await self._maybe_cog_call(self._cog, interaction, interaction.data)
  File "/opt/virtualenvs/python3/lib/python3.8/site-packages/dislash/application_commands/slash_core.py", line 112, in _maybe_cog_call
    return await self(cog, inter, **kwargs)
  File "/opt/virtualenvs/python3/lib/python3.8/site-packages/dislash/application_commands/core.py", line 72, in __call__
    return await self.func(*args, **kwargs)
  File "/home/runner/TheDiscordMathProblemBot/cogs/misc_commands_cog.py", line 86, in list_trusted_users
    await inter.reply(__trusted_users, ephemeral=True)
  File "/opt/virtualenvs/python3/lib/python3.8/site-packages/dislash/interactions/interaction.py", line 227, in reply
    return await self.channel.send(**send_kwargs)  # type: ignore
AttributeError: 'NoneType' object has no attribute 'send'


Wed Nov 24 02:51:26 2021

Traceback (most recent call last):
  File "/opt/virtualenvs/python3/lib/python3.8/site-packages/nextcord/client.py", line 351, in _run_event
    await coro(*args, **kwargs)
  File "main.py", line 244, in on_slash_command_error
    await inter.reply(embed = embed)
  File "/opt/virtualenvs/python3/lib/python3.8/site-packages/dislash/interactions/interaction.py", line 227, in reply
    return await self.channel.send(**send_kwargs)  # type: ignore
AttributeError: 'NoneType' object has no attribute 'send'


Wed Nov 24 02:51:36 2021

Traceback (most recent call last):
  File "/opt/virtualenvs/python3/lib/python3.8/site-packages/dislash/application_commands/slash_client.py", line 1275, in _on_slash_command
    await app_command.invoke(inter)
  File "/opt/virtualenvs/python3/lib/python3.8/site-packages/dislash/application_commands/slash_core.py", line 362, in invoke
    raise err
  File "/opt/virtualenvs/python3/lib/python3.8/site-packages/dislash/application_commands/slash_core.py", line 358, in invoke
    await self._maybe_cog_call(self._cog, interaction, interaction.data)
  File "/opt/virtualenvs/python3/lib/python3.8/site-packages/dislash/application_commands/slash_core.py", line 112, in _maybe_cog_call
    return await self(cog, inter, **kwargs)
  File "/opt/virtualenvs/python3/lib/python3.8/site-packages/dislash/application_commands/core.py", line 72, in __call__
    return await self.func(*args, **kwargs)
  File "/home/runner/TheDiscordMathProblemBot/cogs/misc_commands_cog.py", line 86, in list_trusted_users
    await inter.reply(__trusted_users, ephemeral=True)
  File "/opt/virtualenvs/python3/lib/python3.8/site-packages/dislash/interactions/interaction.py", line 227, in reply
    return await self.channel.send(**send_kwargs)  # type: ignore
  File "/opt/virtualenvs/python3/lib/python3.8/site-packages/dislash/application_commands/_modifications/new.py", line 327, in send
    data = await state.http.send_message(
  File "/opt/virtualenvs/python3/lib/python3.8/site-packages/nextcord/http.py", line 335, in request
    raise HTTPException(response, data)
nextcord.errors.HTTPException: 400 Bad Request (error code: 50006): Cannot send an empty message


Wed Nov 24 02:54:14 2021

Traceback (most recent call last):
  File "/opt/virtualenvs/python3/lib/python3.8/site-packages/dislash/application_commands/slash_client.py", line 1275, in _on_slash_command
    await app_command.invoke(inter)
  File "/opt/virtualenvs/python3/lib/python3.8/site-packages/dislash/application_commands/slash_core.py", line 362, in invoke
    raise err
  File "/opt/virtualenvs/python3/lib/python3.8/site-packages/dislash/application_commands/slash_core.py", line 358, in invoke
    await self._maybe_cog_call(self._cog, interaction, interaction.data)
  File "/opt/virtualenvs/python3/lib/python3.8/site-packages/dislash/application_commands/slash_core.py", line 112, in _maybe_cog_call
    return await self(cog, inter, **kwargs)
  File "/opt/virtualenvs/python3/lib/python3.8/site-packages/dislash/application_commands/core.py", line 72, in __call__
    return await self.func(*args, **kwargs)
  File "/home/runner/TheDiscordMathProblemBot/cogs/misc_commands_cog.py", line 77, in list_trusted_users
    raise Exception("There are no trusted users!")
Exception: There are no trusted users!


Wed Nov 24 02:56:05 2021

Traceback (most recent call last):
  File "/opt/virtualenvs/python3/lib/python3.8/site-packages/dislash/application_commands/slash_client.py", line 1275, in _on_slash_command
    await app_command.invoke(inter)
  File "/opt/virtualenvs/python3/lib/python3.8/site-packages/dislash/application_commands/slash_core.py", line 362, in invoke
    raise err
  File "/opt/virtualenvs/python3/lib/python3.8/site-packages/dislash/application_commands/slash_core.py", line 358, in invoke
    await self._maybe_cog_call(self._cog, interaction, interaction.data)
  File "/opt/virtualenvs/python3/lib/python3.8/site-packages/dislash/application_commands/slash_core.py", line 112, in _maybe_cog_call
    return await self(cog, inter, **kwargs)
  File "/opt/virtualenvs/python3/lib/python3.8/site-packages/dislash/application_commands/core.py", line 72, in __call__
    return await self.func(*args, **kwargs)
  File "/home/runner/TheDiscordMathProblemBot/cogs/misc_commands_cog.py", line 78, in list_trusted_users
    raise Exception("There are no trusted users!")
Exception: There are no trusted users!


