Mon Nov  8 01:06:21 2021

Traceback (most recent call last):
  File "/opt/virtualenvs/python3/lib/python3.8/site-packages/dislash/application_commands/slash_client.py", line 1282, in _on_slash_command
    await app_command.invoke(inter)
  File "/opt/virtualenvs/python3/lib/python3.8/site-packages/dislash/application_commands/slash_core.py", line 216, in invoke
    raise err
  File "/opt/virtualenvs/python3/lib/python3.8/site-packages/dislash/application_commands/slash_core.py", line 212, in invoke
    await self._maybe_cog_call(self._cog, interaction, interaction.data)
  File "/opt/virtualenvs/python3/lib/python3.8/site-packages/dislash/application_commands/slash_core.py", line 37, in _maybe_cog_call
    return await self(inter, **params)
  File "/opt/virtualenvs/python3/lib/python3.8/site-packages/dislash/application_commands/core.py", line 72, in __call__
    return await self.func(*args, **kwargs)
  File "main.py", line 526, in list_all_problems
    if ctx.guild != None and ctx.guild.id not in main_cache.get_guilds():
  File "/home/runner/TheDiscordMathProblemBot/helpful_modules/problems_module.py", line 660, in get_guilds
    #problemsDeleted = 0
  File "/home/runner/TheDiscordMathProblemBot/helpful_modules/problems_module.py", line 504, in update_cache
    return problem2
  File "/home/runner/TheDiscordMathProblemBot/helpful_modules/problems_module.py", line 152, in from_dict
    elif guild_id == "null": #Remove the guild_id null (used for global problems), which is not used anymore because of conflicts with SQL
NameError: name 'self' is not defined


Mon Nov  8 01:08:13 2021

Traceback (most recent call last):
  File "/opt/virtualenvs/python3/lib/python3.8/site-packages/dislash/application_commands/slash_client.py", line 1282, in _on_slash_command
    await app_command.invoke(inter)
  File "/opt/virtualenvs/python3/lib/python3.8/site-packages/dislash/application_commands/slash_core.py", line 216, in invoke
    raise err
  File "/opt/virtualenvs/python3/lib/python3.8/site-packages/dislash/application_commands/slash_core.py", line 212, in invoke
    await self._maybe_cog_call(self._cog, interaction, interaction.data)
  File "/opt/virtualenvs/python3/lib/python3.8/site-packages/dislash/application_commands/slash_core.py", line 37, in _maybe_cog_call
    return await self(inter, **params)
  File "/opt/virtualenvs/python3/lib/python3.8/site-packages/dislash/application_commands/core.py", line 72, in __call__
    return await self.func(*args, **kwargs)
  File "main.py", line 526, in list_all_problems
    if ctx.guild != None and ctx.guild.id not in main_cache.get_guilds():
  File "/home/runner/TheDiscordMathProblemBot/helpful_modules/problems_module.py", line 681, in get_guilds
    self.update_cache()
  File "/home/runner/TheDiscordMathProblemBot/helpful_modules/problems_module.py", line 518, in update_cache
    problem = MathProblem.from_dict(self._sql_dict[key], cache = copy(self))
  File "/home/runner/TheDiscordMathProblemBot/helpful_modules/problems_module.py", line 165, in from_dict
    cache.remove_problem_without_returning(Problem.guild_id, Problem.id) #There will be a recursion error if I normally delete a problem
  File "/home/runner/TheDiscordMathProblemBot/helpful_modules/problems_module.py", line 650, in remove_problem_without_returning
    connection.cursor().execute("DELETE FROM kv_store WHERE Key = (?)", (self._sqldict.name))
AttributeError: 'MathProblemCache' object has no attribute '_sqldict'


Mon Nov  8 01:11:19 2021

Traceback (most recent call last):
  File "/opt/virtualenvs/python3/lib/python3.8/site-packages/dislash/application_commands/slash_client.py", line 1282, in _on_slash_command
    await app_command.invoke(inter)
  File "/opt/virtualenvs/python3/lib/python3.8/site-packages/dislash/application_commands/slash_core.py", line 216, in invoke
    raise err
  File "/opt/virtualenvs/python3/lib/python3.8/site-packages/dislash/application_commands/slash_core.py", line 212, in invoke
    await self._maybe_cog_call(self._cog, interaction, interaction.data)
  File "/opt/virtualenvs/python3/lib/python3.8/site-packages/dislash/application_commands/slash_core.py", line 37, in _maybe_cog_call
    return await self(inter, **params)
  File "/opt/virtualenvs/python3/lib/python3.8/site-packages/dislash/application_commands/core.py", line 72, in __call__
    return await self.func(*args, **kwargs)
  File "main.py", line 526, in list_all_problems
    if ctx.guild != None and ctx.guild.id not in main_cache.get_guilds():
  File "/home/runner/TheDiscordMathProblemBot/helpful_modules/problems_module.py", line 681, in get_guilds
    self.update_cache()
  File "/home/runner/TheDiscordMathProblemBot/helpful_modules/problems_module.py", line 518, in update_cache
    problem = MathProblem.from_dict(self._sql_dict[key], cache = copy(self))
  File "/home/runner/TheDiscordMathProblemBot/helpful_modules/problems_module.py", line 165, in from_dict
    cache.remove_problem_without_returning(Problem.guild_id, Problem.id) #There will be a recursion error if I normally delete a problem
  File "/home/runner/TheDiscordMathProblemBot/helpful_modules/problems_module.py", line 650, in remove_problem_without_returning
    connection.cursor().execute("DELETE FROM kv_store WHERE Key = (?)", (self._sqldict.name))
AttributeError: 'MathProblemCache' object has no attribute '_sqldict'


Mon Nov  8 01:11:45 2021

Traceback (most recent call last):
  File "/opt/virtualenvs/python3/lib/python3.8/site-packages/dislash/application_commands/slash_client.py", line 1282, in _on_slash_command
    await app_command.invoke(inter)
  File "/opt/virtualenvs/python3/lib/python3.8/site-packages/dislash/application_commands/slash_core.py", line 216, in invoke
    raise err
  File "/opt/virtualenvs/python3/lib/python3.8/site-packages/dislash/application_commands/slash_core.py", line 212, in invoke
    await self._maybe_cog_call(self._cog, interaction, interaction.data)
  File "/opt/virtualenvs/python3/lib/python3.8/site-packages/dislash/application_commands/slash_core.py", line 37, in _maybe_cog_call
    return await self(inter, **params)
  File "/opt/virtualenvs/python3/lib/python3.8/site-packages/dislash/application_commands/core.py", line 72, in __call__
    return await self.func(*args, **kwargs)
  File "main.py", line 526, in list_all_problems
    if ctx.guild != None and ctx.guild.id not in main_cache.get_guilds():
  File "/home/runner/TheDiscordMathProblemBot/helpful_modules/problems_module.py", line 681, in get_guilds
    self.update_cache()
  File "/home/runner/TheDiscordMathProblemBot/helpful_modules/problems_module.py", line 518, in update_cache
    problem = MathProblem.from_dict(self._sql_dict[key], cache = copy(self))
  File "/home/runner/TheDiscordMathProblemBot/helpful_modules/problems_module.py", line 165, in from_dict
    cache.remove_problem_without_returning(Problem.guild_id, Problem.id) #There will be a recursion error if I normally delete a problem
  File "/home/runner/TheDiscordMathProblemBot/helpful_modules/problems_module.py", line 650, in remove_problem_without_returning
    connection.cursor().execute("DELETE FROM kv_store WHERE Key = (?)", (self._sql_dict.name))
sqlite3.ProgrammingError: Incorrect number of bindings supplied. The current statement uses 1, and there are 20 supplied.


Mon Nov  8 01:12:35 2021

Traceback (most recent call last):
  File "/opt/virtualenvs/python3/lib/python3.8/site-packages/dislash/application_commands/slash_client.py", line 1282, in _on_slash_command
    await app_command.invoke(inter)
  File "/opt/virtualenvs/python3/lib/python3.8/site-packages/dislash/application_commands/slash_core.py", line 216, in invoke
    raise err
  File "/opt/virtualenvs/python3/lib/python3.8/site-packages/dislash/application_commands/slash_core.py", line 212, in invoke
    await self._maybe_cog_call(self._cog, interaction, interaction.data)
  File "/opt/virtualenvs/python3/lib/python3.8/site-packages/dislash/application_commands/slash_core.py", line 37, in _maybe_cog_call
    return await self(inter, **params)
  File "/opt/virtualenvs/python3/lib/python3.8/site-packages/dislash/application_commands/core.py", line 72, in __call__
    return await self.func(*args, **kwargs)
  File "main.py", line 526, in list_all_problems
    if ctx.guild != None and ctx.guild.id not in main_cache.get_guilds():
  File "/home/runner/TheDiscordMathProblemBot/helpful_modules/problems_module.py", line 681, in get_guilds
    self.update_cache()
  File "/home/runner/TheDiscordMathProblemBot/helpful_modules/problems_module.py", line 518, in update_cache
    problem = MathProblem.from_dict(self._sql_dict[key], cache = copy(self))
  File "/home/runner/TheDiscordMathProblemBot/helpful_modules/problems_module.py", line 165, in from_dict
    cache.remove_problem_without_returning(Problem.guild_id, Problem.id) #There will be a recursion error if I normally delete a problem
  File "/home/runner/TheDiscordMathProblemBot/helpful_modules/problems_module.py", line 650, in remove_problem_without_returning
    connection.cursor().execute("DELETE FROM kv_store WHERE Key = ?", (key))
sqlite3.ProgrammingError: Incorrect number of bindings supplied. The current statement uses 1, and there are 22 supplied.


