Mon Oct 25 00:14:01 2021

Traceback (most recent call last):
  File "/opt/virtualenvs/python3/lib/python3.8/site-packages/nextcord/enums.py", line 139, in __call__
    return cls._enum_value_map_[value]
KeyError: <SlashInteraction id=901986925794172968 version=1 type=2 token='aW50ZXJhY3Rpb246OTAxOTg2OTI1Nzk0MTcyOTY4Okw3RU42ZER4WFNVS25CNURoOTNCOVhxcEh2MWdodkpQNE9PYkpBVUVRbzNJa3RFanRkdGlBWmdnMHVySGVmbmVEU2szM3JITE9QTFM3Y2VjT3dmcThGOVNlOXp0cjQyNU5EbWo5Ym5yaFk3QkNwRW5VdnpEV3RuRVhEZE9wSWx5' guild=The Discord math problem bot server channel=thisisatestchannel author=ay136416#2707 data=<SlashInteractionData id=901879020990386228 type=1 name='submit_a_request' options={'extra_info': <InteractionDataOption name='extra_info' value=testing 123 options={}>}>>

During handling of the above exception, another exception occurred:

Traceback (most recent call last):
  File "/opt/virtualenvs/python3/lib/python3.8/site-packages/dislash/application_commands/slash_client.py", line 1282, in _on_slash_command
    await app_command.invoke(inter)
  File "/opt/virtualenvs/python3/lib/python3.8/site-packages/dislash/application_commands/slash_core.py", line 216, in invoke
    raise err
  File "/opt/virtualenvs/python3/lib/python3.8/site-packages/dislash/application_commands/slash_core.py", line 210, in invoke
    self._prepare_cooldowns(interaction)
  File "/opt/virtualenvs/python3/lib/python3.8/site-packages/dislash/application_commands/core.py", line 78, in _prepare_cooldowns
    bucket = self._buckets.get_bucket(inter, current)
  File "/opt/virtualenvs/python3/lib/python3.8/site-packages/discord/ext/commands/cooldowns.py", line 173, in get_bucket
    key = self._bucket_key(message)
  File "/opt/virtualenvs/python3/lib/python3.8/site-packages/discord/ext/commands/cooldowns.py", line 157, in _bucket_key
    return self._cooldown.type(msg)
  File "/opt/virtualenvs/python3/lib/python3.8/site-packages/nextcord/enums.py", line 141, in __call__
    raise ValueError(f"{value!r} is not a valid {cls.__name__}")
ValueError: <SlashInteraction id=901986925794172968 version=1 type=2 token='aW50ZXJhY3Rpb246OTAxOTg2OTI1Nzk0MTcyOTY4Okw3RU42ZER4WFNVS25CNURoOTNCOVhxcEh2MWdodkpQNE9PYkpBVUVRbzNJa3RFanRkdGlBWmdnMHVySGVmbmVEU2szM3JITE9QTFM3Y2VjT3dmcThGOVNlOXp0cjQyNU5EbWo5Ym5yaFk3QkNwRW5VdnpEV3RuRVhEZE9wSWx5' guild=The Discord math problem bot server channel=thisisatestchannel author=ay136416#2707 data=<SlashInteractionData id=901879020990386228 type=1 name='submit_a_request' options={'extra_info': <InteractionDataOption name='extra_info' value=testing 123 options={}>}>> is not a valid BucketType


Mon Oct 25 00:15:26 2021

Traceback (most recent call last):
  File "/opt/virtualenvs/python3/lib/python3.8/site-packages/nextcord/enums.py", line 139, in __call__
    return cls._enum_value_map_[value]
KeyError: <SlashInteraction id=901987281752186991 version=1 type=2 token='aW50ZXJhY3Rpb246OTAxOTg3MjgxNzUyMTg2OTkxOmNhdU5yNUZkV1N2bUlhcDJNN3k4TDZuTlREOVc2TjFLQkNmYVAxS0pXRkFDM3NtMEJUWDF3ZWRFbzg2UjVSMGRNV1U0UVJFNVJyVXJic3BYR1BFTTczZ3BYRG1JalJOeElSdnJONEt5c0lKeWlTV0laQUNFNmFMWUNrSE9lMTZt' guild=The Discord math problem bot server channel=thisisatestchannel author=ay136416#2707 data=<SlashInteractionData id=901879020990386228 type=1 name='submit_a_request' options={'extra_info': <InteractionDataOption name='extra_info' value=testing 1 2 3 options={}>}>>

During handling of the above exception, another exception occurred:

Traceback (most recent call last):
  File "/opt/virtualenvs/python3/lib/python3.8/site-packages/dislash/application_commands/slash_client.py", line 1282, in _on_slash_command
    await app_command.invoke(inter)
  File "/opt/virtualenvs/python3/lib/python3.8/site-packages/dislash/application_commands/slash_core.py", line 216, in invoke
    raise err
  File "/opt/virtualenvs/python3/lib/python3.8/site-packages/dislash/application_commands/slash_core.py", line 210, in invoke
    self._prepare_cooldowns(interaction)
  File "/opt/virtualenvs/python3/lib/python3.8/site-packages/dislash/application_commands/core.py", line 78, in _prepare_cooldowns
    bucket = self._buckets.get_bucket(inter, current)
  File "/opt/virtualenvs/python3/lib/python3.8/site-packages/discord/ext/commands/cooldowns.py", line 173, in get_bucket
    key = self._bucket_key(message)
  File "/opt/virtualenvs/python3/lib/python3.8/site-packages/discord/ext/commands/cooldowns.py", line 157, in _bucket_key
    return self._cooldown.type(msg)
  File "/opt/virtualenvs/python3/lib/python3.8/site-packages/nextcord/enums.py", line 141, in __call__
    raise ValueError(f"{value!r} is not a valid {cls.__name__}")
ValueError: <SlashInteraction id=901987281752186991 version=1 type=2 token='aW50ZXJhY3Rpb246OTAxOTg3MjgxNzUyMTg2OTkxOmNhdU5yNUZkV1N2bUlhcDJNN3k4TDZuTlREOVc2TjFLQkNmYVAxS0pXRkFDM3NtMEJUWDF3ZWRFbzg2UjVSMGRNV1U0UVJFNVJyVXJic3BYR1BFTTczZ3BYRG1JalJOeElSdnJONEt5c0lKeWlTV0laQUNFNmFMWUNrSE9lMTZt' guild=The Discord math problem bot server channel=thisisatestchannel author=ay136416#2707 data=<SlashInteractionData id=901879020990386228 type=1 name='submit_a_request' options={'extra_info': <InteractionDataOption name='extra_info' value=testing 1 2 3 options={}>}>> is not a valid BucketType


Mon Oct 25 00:17:44 2021

Traceback (most recent call last):
  File "/opt/virtualenvs/python3/lib/python3.8/site-packages/nextcord/enums.py", line 139, in __call__
    return cls._enum_value_map_[value]
KeyError: <SlashInteraction id=901987863774773288 version=1 type=2 token='aW50ZXJhY3Rpb246OTAxOTg3ODYzNzc0NzczMjg4OnN4cEpNZXlqaXlGaTZ5Q2Vwd1ZCbVNLRU5DcjJTV25PV3N0YkdLNlhrbUNPZmlXdDF4T1MySFM3eENVVU5FSE8zVTBGMlJQc0pTSHlKUmp2RUxTTkhYdlByTFdvaHNvVTNoZk1iejQwZWlNVjF6OFNaaVZ0UEp2TktjZHdPOXVE' guild=The Discord math problem bot server channel=thisisatestchannel author=ay136416#2707 data=<SlashInteractionData id=901879020990386228 type=1 name='submit_a_request' options={'extra_info': <InteractionDataOption name='extra_info' value=testing 1 2 3 options={}>}>>

During handling of the above exception, another exception occurred:

Traceback (most recent call last):
  File "/opt/virtualenvs/python3/lib/python3.8/site-packages/dislash/application_commands/slash_client.py", line 1282, in _on_slash_command
    await app_command.invoke(inter)
  File "/opt/virtualenvs/python3/lib/python3.8/site-packages/dislash/application_commands/slash_core.py", line 216, in invoke
    raise err
  File "/opt/virtualenvs/python3/lib/python3.8/site-packages/dislash/application_commands/slash_core.py", line 210, in invoke
    self._prepare_cooldowns(interaction)
  File "/opt/virtualenvs/python3/lib/python3.8/site-packages/dislash/application_commands/core.py", line 78, in _prepare_cooldowns
    bucket = self._buckets.get_bucket(inter, current)
  File "/opt/virtualenvs/python3/lib/python3.8/site-packages/discord/ext/commands/cooldowns.py", line 173, in get_bucket
    key = self._bucket_key(message)
  File "/opt/virtualenvs/python3/lib/python3.8/site-packages/discord/ext/commands/cooldowns.py", line 157, in _bucket_key
    return self._cooldown.type(msg)
  File "/opt/virtualenvs/python3/lib/python3.8/site-packages/nextcord/enums.py", line 141, in __call__
    raise ValueError(f"{value!r} is not a valid {cls.__name__}")
ValueError: <SlashInteraction id=901987863774773288 version=1 type=2 token='aW50ZXJhY3Rpb246OTAxOTg3ODYzNzc0NzczMjg4OnN4cEpNZXlqaXlGaTZ5Q2Vwd1ZCbVNLRU5DcjJTV25PV3N0YkdLNlhrbUNPZmlXdDF4T1MySFM3eENVVU5FSE8zVTBGMlJQc0pTSHlKUmp2RUxTTkhYdlByTFdvaHNvVTNoZk1iejQwZWlNVjF6OFNaaVZ0UEp2TktjZHdPOXVE' guild=The Discord math problem bot server channel=thisisatestchannel author=ay136416#2707 data=<SlashInteractionData id=901879020990386228 type=1 name='submit_a_request' options={'extra_info': <InteractionDataOption name='extra_info' value=testing 1 2 3 options={}>}>> is not a valid BucketType


Mon Oct 25 00:18:57 2021

Traceback (most recent call last):
  File "/opt/virtualenvs/python3/lib/python3.8/site-packages/dislash/application_commands/slash_client.py", line 1282, in _on_slash_command
    await app_command.invoke(inter)
  File "/opt/virtualenvs/python3/lib/python3.8/site-packages/dislash/application_commands/slash_core.py", line 216, in invoke
    raise err
  File "/opt/virtualenvs/python3/lib/python3.8/site-packages/dislash/application_commands/slash_core.py", line 212, in invoke
    await self._maybe_cog_call(self._cog, interaction, interaction.data)
  File "/opt/virtualenvs/python3/lib/python3.8/site-packages/dislash/application_commands/slash_core.py", line 37, in _maybe_cog_call
    return await self(inter, **params)
  File "/opt/virtualenvs/python3/lib/python3.8/site-packages/dislash/application_commands/core.py", line 72, in __call__
    return await self.func(*args, **kwargs)
  File "main.py", line 725, in submit_a_request
    channel = await bot.fetch_channel(id=901464948604039209) # CHANGE THIS IF YOU HAVE A DIFFERENT REQUESTS CHANNEL! (the part after id)
TypeError: fetch_channel() got an unexpected keyword argument 'id'


Mon Oct 25 00:19:35 2021

Traceback (most recent call last):
  File "/opt/virtualenvs/python3/lib/python3.8/site-packages/dislash/application_commands/slash_client.py", line 1282, in _on_slash_command
    await app_command.invoke(inter)
  File "/opt/virtualenvs/python3/lib/python3.8/site-packages/dislash/application_commands/slash_core.py", line 216, in invoke
    raise err
  File "/opt/virtualenvs/python3/lib/python3.8/site-packages/dislash/application_commands/slash_core.py", line 212, in invoke
    await self._maybe_cog_call(self._cog, interaction, interaction.data)
  File "/opt/virtualenvs/python3/lib/python3.8/site-packages/dislash/application_commands/slash_core.py", line 37, in _maybe_cog_call
    return await self(inter, **params)
  File "/opt/virtualenvs/python3/lib/python3.8/site-packages/dislash/application_commands/core.py", line 72, in __call__
    return await self.func(*args, **kwargs)
  File "main.py", line 727, in submit_a_request
    Problem = main_cache.get_problem(guild_id, problem_id)
NameError: name 'guild_id' is not defined


Mon Oct 25 00:20:09 2021

Traceback (most recent call last):
  File "/opt/virtualenvs/python3/lib/python3.8/site-packages/dislash/application_commands/slash_client.py", line 1282, in _on_slash_command
    await app_command.invoke(inter)
  File "/opt/virtualenvs/python3/lib/python3.8/site-packages/dislash/application_commands/slash_core.py", line 216, in invoke
    raise err
  File "/opt/virtualenvs/python3/lib/python3.8/site-packages/dislash/application_commands/slash_core.py", line 212, in invoke
    await self._maybe_cog_call(self._cog, interaction, interaction.data)
  File "/opt/virtualenvs/python3/lib/python3.8/site-packages/dislash/application_commands/slash_core.py", line 37, in _maybe_cog_call
    return await self(inter, **params)
  File "/opt/virtualenvs/python3/lib/python3.8/site-packages/dislash/application_commands/core.py", line 72, in __call__
    return await self.func(*args, **kwargs)
  File "main.py", line 727, in submit_a_request
    Problem = main_cache.get_problem(offending_problem_guild_id, offending_problem_id)
  File "/home/runner/TheDiscordMathProblemBot/problems_module.py", line 473, in get_problem
    raise TypeError("guild_id is not a string")
TypeError: guild_id is not a string


Mon Oct 25 00:21:19 2021

Traceback (most recent call last):
  File "/opt/virtualenvs/python3/lib/python3.8/site-packages/dislash/application_commands/slash_client.py", line 1282, in _on_slash_command
    await app_command.invoke(inter)
  File "/opt/virtualenvs/python3/lib/python3.8/site-packages/dislash/application_commands/slash_core.py", line 216, in invoke
    raise err
  File "/opt/virtualenvs/python3/lib/python3.8/site-packages/dislash/application_commands/slash_core.py", line 212, in invoke
    await self._maybe_cog_call(self._cog, interaction, interaction.data)
  File "/opt/virtualenvs/python3/lib/python3.8/site-packages/dislash/application_commands/slash_core.py", line 37, in _maybe_cog_call
    return await self(inter, **params)
  File "/opt/virtualenvs/python3/lib/python3.8/site-packages/dislash/application_commands/core.py", line 72, in __call__
    return await self.func(*args, **kwargs)
  File "main.py", line 739, in submit_a_request
    embed.description += f"""Copyrighted thing: (if legal): {copyrighted_thing}
TypeError: unsupported operand type(s) for +=: '_EmptyEmbed' and 'str'


Mon Oct 25 00:21:52 2021

Traceback (most recent call last):
  File "/opt/virtualenvs/python3/lib/python3.8/site-packages/dislash/application_commands/slash_client.py", line 1282, in _on_slash_command
    await app_command.invoke(inter)
  File "/opt/virtualenvs/python3/lib/python3.8/site-packages/dislash/application_commands/slash_core.py", line 216, in invoke
    raise err
  File "/opt/virtualenvs/python3/lib/python3.8/site-packages/dislash/application_commands/slash_core.py", line 212, in invoke
    await self._maybe_cog_call(self._cog, interaction, interaction.data)
  File "/opt/virtualenvs/python3/lib/python3.8/site-packages/dislash/application_commands/slash_core.py", line 37, in _maybe_cog_call
    return await self(inter, **params)
  File "/opt/virtualenvs/python3/lib/python3.8/site-packages/dislash/application_commands/core.py", line 72, in __call__
    return await self.func(*args, **kwargs)
  File "main.py", line 739, in submit_a_request
    embed.description += f"""Copyrighted thing: (if legal): {copyrighted_thing}
TypeError: unsupported operand type(s) for +=: '_EmptyEmbed' and 'str'


Mon Oct 25 00:23:14 2021

Traceback (most recent call last):
  File "/opt/virtualenvs/python3/lib/python3.8/site-packages/dislash/application_commands/slash_client.py", line 1282, in _on_slash_command
    await app_command.invoke(inter)
  File "/opt/virtualenvs/python3/lib/python3.8/site-packages/dislash/application_commands/slash_core.py", line 216, in invoke
    raise err
  File "/opt/virtualenvs/python3/lib/python3.8/site-packages/dislash/application_commands/slash_core.py", line 212, in invoke
    await self._maybe_cog_call(self._cog, interaction, interaction.data)
  File "/opt/virtualenvs/python3/lib/python3.8/site-packages/dislash/application_commands/slash_core.py", line 37, in _maybe_cog_call
    return await self(inter, **params)
  File "/opt/virtualenvs/python3/lib/python3.8/site-packages/dislash/application_commands/core.py", line 72, in __call__
    return await self.func(*args, **kwargs)
  File "main.py", line 743, in submit_a_request
    embed._footer += asctime()
AttributeError: _footer


Mon Oct 25 00:24:43 2021

Traceback (most recent call last):
  File "/opt/virtualenvs/python3/lib/python3.8/site-packages/dislash/application_commands/slash_client.py", line 1282, in _on_slash_command
    await app_command.invoke(inter)
  File "/opt/virtualenvs/python3/lib/python3.8/site-packages/dislash/application_commands/slash_core.py", line 216, in invoke
    raise err
  File "/opt/virtualenvs/python3/lib/python3.8/site-packages/dislash/application_commands/slash_core.py", line 212, in invoke
    await self._maybe_cog_call(self._cog, interaction, interaction.data)
  File "/opt/virtualenvs/python3/lib/python3.8/site-packages/dislash/application_commands/slash_core.py", line 37, in _maybe_cog_call
    return await self(inter, **params)
  File "/opt/virtualenvs/python3/lib/python3.8/site-packages/dislash/application_commands/core.py", line 72, in __call__
    return await self.func(*args, **kwargs)
  File "main.py", line 744, in submit_a_request
    embed.set_footer(asctime())
TypeError: set_footer() takes 1 positional argument but 2 were given


Mon Oct 25 00:25:14 2021

Traceback (most recent call last):
  File "/opt/virtualenvs/python3/lib/python3.8/site-packages/dislash/application_commands/slash_client.py", line 1282, in _on_slash_command
    await app_command.invoke(inter)
  File "/opt/virtualenvs/python3/lib/python3.8/site-packages/dislash/application_commands/slash_core.py", line 216, in invoke
    raise err
  File "/opt/virtualenvs/python3/lib/python3.8/site-packages/dislash/application_commands/slash_core.py", line 212, in invoke
    await self._maybe_cog_call(self._cog, interaction, interaction.data)
  File "/opt/virtualenvs/python3/lib/python3.8/site-packages/dislash/application_commands/slash_core.py", line 37, in _maybe_cog_call
    return await self(inter, **params)
  File "/opt/virtualenvs/python3/lib/python3.8/site-packages/dislash/application_commands/core.py", line 72, in __call__
    return await self.func(*args, **kwargs)
  File "main.py", line 751, in submit_a_request
    await inter.reply("Your request has been submitted!")
NameError: name 'inter' is not defined


Mon Oct 25 00:26:24 2021

Traceback (most recent call last):
  File "/opt/virtualenvs/python3/lib/python3.8/site-packages/dislash/application_commands/slash_client.py", line 1282, in _on_slash_command
    await app_command.invoke(inter)
  File "/opt/virtualenvs/python3/lib/python3.8/site-packages/dislash/application_commands/slash_core.py", line 216, in invoke
    raise err
  File "/opt/virtualenvs/python3/lib/python3.8/site-packages/dislash/application_commands/slash_core.py", line 212, in invoke
    await self._maybe_cog_call(self._cog, interaction, interaction.data)
  File "/opt/virtualenvs/python3/lib/python3.8/site-packages/dislash/application_commands/slash_core.py", line 37, in _maybe_cog_call
    return await self(inter, **params)
  File "/opt/virtualenvs/python3/lib/python3.8/site-packages/dislash/application_commands/core.py", line 72, in __call__
    return await self.func(*args, **kwargs)
  File "main.py", line 751, in submit_a_request
    await inter.reply("Your request has been submitted!")
NameError: name 'inter' is not defined


Mon Oct 25 00:26:36 2021

Traceback (most recent call last):
  File "/opt/virtualenvs/python3/lib/python3.8/site-packages/dislash/application_commands/slash_client.py", line 1282, in _on_slash_command
    await app_command.invoke(inter)
  File "/opt/virtualenvs/python3/lib/python3.8/site-packages/dislash/application_commands/slash_core.py", line 216, in invoke
    raise err
  File "/opt/virtualenvs/python3/lib/python3.8/site-packages/dislash/application_commands/slash_core.py", line 212, in invoke
    await self._maybe_cog_call(self._cog, interaction, interaction.data)
  File "/opt/virtualenvs/python3/lib/python3.8/site-packages/dislash/application_commands/slash_core.py", line 37, in _maybe_cog_call
    return await self(inter, **params)
  File "/opt/virtualenvs/python3/lib/python3.8/site-packages/dislash/application_commands/core.py", line 72, in __call__
    return await self.func(*args, **kwargs)
  File "main.py", line 733, in submit_a_request
    embed = nextcord.Embed(title = f"A new request has been recieved from {ctx.author.name}#{ctx.author.discriminator}!", description = "")
NameError: name 'ctx' is not defined


Mon Oct 25 00:34:19 2021

Traceback (most recent call last):
  File "/opt/virtualenvs/python3/lib/python3.8/site-packages/dislash/application_commands/slash_client.py", line 1282, in _on_slash_command
    await app_command.invoke(inter)
  File "/opt/virtualenvs/python3/lib/python3.8/site-packages/dislash/application_commands/slash_core.py", line 216, in invoke
    raise err
  File "/opt/virtualenvs/python3/lib/python3.8/site-packages/dislash/application_commands/slash_core.py", line 212, in invoke
    await self._maybe_cog_call(self._cog, interaction, interaction.data)
  File "/opt/virtualenvs/python3/lib/python3.8/site-packages/dislash/application_commands/slash_core.py", line 37, in _maybe_cog_call
    return await self(inter, **params)
  File "/opt/virtualenvs/python3/lib/python3.8/site-packages/dislash/application_commands/core.py", line 72, in __call__
    return await self.func(*args, **kwargs)
  File "main.py", line 419, in submit_problem
    main_cache.add_problem(problem_id=problem_id,
  File "/home/runner/TheDiscordMathProblemBot/problems_module.py", line 522, in add_problem
    raise TypeError("problem_id is not a string.")
TypeError: problem_id is not a string.


Mon Oct 25 00:35:56 2021

Traceback (most recent call last):
  File "/opt/virtualenvs/python3/lib/python3.8/site-packages/dislash/application_commands/slash_client.py", line 1282, in _on_slash_command
    await app_command.invoke(inter)
  File "/opt/virtualenvs/python3/lib/python3.8/site-packages/dislash/application_commands/slash_core.py", line 216, in invoke
    raise err
  File "/opt/virtualenvs/python3/lib/python3.8/site-packages/dislash/application_commands/slash_core.py", line 212, in invoke
    await self._maybe_cog_call(self._cog, interaction, interaction.data)
  File "/opt/virtualenvs/python3/lib/python3.8/site-packages/dislash/application_commands/slash_core.py", line 37, in _maybe_cog_call
    return await self(inter, **params)
  File "/opt/virtualenvs/python3/lib/python3.8/site-packages/dislash/application_commands/core.py", line 72, in __call__
    return await self.func(*args, **kwargs)
  File "main.py", line 419, in submit_problem
    main_cache.add_problem(problem_id=problem_id,
  File "/home/runner/TheDiscordMathProblemBot/problems_module.py", line 522, in add_problem
    raise TypeError("problem_id is not a string.")
TypeError: problem_id is not a string.


Mon Oct 25 00:36:26 2021

Traceback (most recent call last):
  File "/opt/virtualenvs/python3/lib/python3.8/site-packages/dislash/application_commands/slash_client.py", line 1282, in _on_slash_command
    await app_command.invoke(inter)
  File "/opt/virtualenvs/python3/lib/python3.8/site-packages/dislash/application_commands/slash_core.py", line 216, in invoke
    raise err
  File "/opt/virtualenvs/python3/lib/python3.8/site-packages/dislash/application_commands/slash_core.py", line 212, in invoke
    await self._maybe_cog_call(self._cog, interaction, interaction.data)
  File "/opt/virtualenvs/python3/lib/python3.8/site-packages/dislash/application_commands/slash_core.py", line 37, in _maybe_cog_call
    return await self(inter, **params)
  File "/opt/virtualenvs/python3/lib/python3.8/site-packages/dislash/application_commands/core.py", line 72, in __call__
    return await self.func(*args, **kwargs)
  File "main.py", line 419, in submit_problem
    main_cache.add_problem(problem_id=str(problem_id),
  File "/home/runner/TheDiscordMathProblemBot/problems_module.py", line 523, in add_problem
    if len(self.guild_problems[guild_id]) > self.max_guild_problems:
KeyError: 'null'


Mon Oct 25 00:40:37 2021

Traceback (most recent call last):
  File "/opt/virtualenvs/python3/lib/python3.8/site-packages/dislash/application_commands/slash_client.py", line 1282, in _on_slash_command
    await app_command.invoke(inter)
  File "/opt/virtualenvs/python3/lib/python3.8/site-packages/dislash/application_commands/slash_core.py", line 216, in invoke
    raise err
  File "/opt/virtualenvs/python3/lib/python3.8/site-packages/dislash/application_commands/slash_core.py", line 212, in invoke
    await self._maybe_cog_call(self._cog, interaction, interaction.data)
  File "/opt/virtualenvs/python3/lib/python3.8/site-packages/dislash/application_commands/slash_core.py", line 37, in _maybe_cog_call
    return await self(inter, **params)
  File "/opt/virtualenvs/python3/lib/python3.8/site-packages/dislash/application_commands/core.py", line 72, in __call__
    return await self.func(*args, **kwargs)
  File "main.py", line 409, in submit_problem
    if problem_id not in [problem.id for problem in main_cache.get_global_problems()]:
TypeError: 'MathProblem' object is not iterable


Mon Oct 25 00:42:36 2021

Traceback (most recent call last):
  File "/opt/virtualenvs/python3/lib/python3.8/site-packages/dislash/application_commands/slash_client.py", line 1282, in _on_slash_command
    await app_command.invoke(inter)
  File "/opt/virtualenvs/python3/lib/python3.8/site-packages/dislash/application_commands/slash_core.py", line 216, in invoke
    raise err
  File "/opt/virtualenvs/python3/lib/python3.8/site-packages/dislash/application_commands/slash_core.py", line 212, in invoke
    await self._maybe_cog_call(self._cog, interaction, interaction.data)
  File "/opt/virtualenvs/python3/lib/python3.8/site-packages/dislash/application_commands/slash_core.py", line 37, in _maybe_cog_call
    return await self(inter, **params)
  File "/opt/virtualenvs/python3/lib/python3.8/site-packages/dislash/application_commands/core.py", line 72, in __call__
    return await self.func(*args, **kwargs)
  File "main.py", line 410, in submit_problem
    if problem_id not in [problem.id for problem in main_cache.get_global_problems()]:
TypeError: 'MathProblem' object is not iterable


Mon Oct 25 00:43:21 2021

Traceback (most recent call last):
  File "/opt/virtualenvs/python3/lib/python3.8/site-packages/dislash/application_commands/slash_client.py", line 1282, in _on_slash_command
    await app_command.invoke(inter)
  File "/opt/virtualenvs/python3/lib/python3.8/site-packages/dislash/application_commands/slash_core.py", line 216, in invoke
    raise err
  File "/opt/virtualenvs/python3/lib/python3.8/site-packages/dislash/application_commands/slash_core.py", line 212, in invoke
    await self._maybe_cog_call(self._cog, interaction, interaction.data)
  File "/opt/virtualenvs/python3/lib/python3.8/site-packages/dislash/application_commands/slash_core.py", line 37, in _maybe_cog_call
    return await self(inter, **params)
  File "/opt/virtualenvs/python3/lib/python3.8/site-packages/dislash/application_commands/core.py", line 72, in __call__
    return await self.func(*args, **kwargs)
  File "main.py", line 410, in submit_problem
    if problem_id not in [problem.id for problem in main_cache.get_global_problems()]:
TypeError: 'MathProblem' object is not iterable


Mon Oct 25 00:56:19 2021

Traceback (most recent call last):
  File "/opt/virtualenvs/python3/lib/python3.8/site-packages/dislash/application_commands/slash_client.py", line 1282, in _on_slash_command
    await app_command.invoke(inter)
  File "/opt/virtualenvs/python3/lib/python3.8/site-packages/dislash/application_commands/slash_core.py", line 216, in invoke
    raise err
  File "/opt/virtualenvs/python3/lib/python3.8/site-packages/dislash/application_commands/slash_core.py", line 212, in invoke
    await self._maybe_cog_call(self._cog, interaction, interaction.data)
  File "/opt/virtualenvs/python3/lib/python3.8/site-packages/dislash/application_commands/slash_core.py", line 37, in _maybe_cog_call
    return await self(inter, **params)
  File "/opt/virtualenvs/python3/lib/python3.8/site-packages/dislash/application_commands/core.py", line 72, in __call__
    return await self.func(*args, **kwargs)
  File "main.py", line 643, in delete_problem
    if problem_id not in main_cache.get_guild_problems(ctx.guild).keys():
AttributeError: 'list' object has no attribute 'keys'


Mon Oct 25 00:57:51 2021

Traceback (most recent call last):
  File "/opt/virtualenvs/python3/lib/python3.8/site-packages/dislash/application_commands/slash_client.py", line 1282, in _on_slash_command
    await app_command.invoke(inter)
  File "/opt/virtualenvs/python3/lib/python3.8/site-packages/dislash/application_commands/slash_core.py", line 216, in invoke
    raise err
  File "/opt/virtualenvs/python3/lib/python3.8/site-packages/dislash/application_commands/slash_core.py", line 212, in invoke
    await self._maybe_cog_call(self._cog, interaction, interaction.data)
  File "/opt/virtualenvs/python3/lib/python3.8/site-packages/dislash/application_commands/slash_core.py", line 37, in _maybe_cog_call
    return await self(inter, **params)
  File "/opt/virtualenvs/python3/lib/python3.8/site-packages/dislash/application_commands/core.py", line 72, in __call__
    return await self.func(*args, **kwargs)
  File "main.py", line 351, in submit_problem
    if ctx.guild != None and ctx.guild.id not in main_cache.get_guilds():
  File "/home/runner/TheDiscordMathProblemBot/problems_module.py", line 603, in get_guilds
    self.update_cache()
  File "/home/runner/TheDiscordMathProblemBot/problems_module.py", line 459, in update_cache
    problem = MathProblem.from_dict(self._sqldict[key])
AttributeError: 'MathProblemCache' object has no attribute '_sqldict'


Mon Oct 25 00:57:57 2021

Traceback (most recent call last):
  File "/opt/virtualenvs/python3/lib/python3.8/site-packages/dislash/application_commands/slash_client.py", line 1282, in _on_slash_command
    await app_command.invoke(inter)
  File "/opt/virtualenvs/python3/lib/python3.8/site-packages/dislash/application_commands/slash_core.py", line 216, in invoke
    raise err
  File "/opt/virtualenvs/python3/lib/python3.8/site-packages/dislash/application_commands/slash_core.py", line 212, in invoke
    await self._maybe_cog_call(self._cog, interaction, interaction.data)
  File "/opt/virtualenvs/python3/lib/python3.8/site-packages/dislash/application_commands/slash_core.py", line 37, in _maybe_cog_call
    return await self(inter, **params)
  File "/opt/virtualenvs/python3/lib/python3.8/site-packages/dislash/application_commands/core.py", line 72, in __call__
    return await self.func(*args, **kwargs)
  File "main.py", line 643, in delete_problem
    if problem_id not in main_cache.get_guild_problems(ctx.guild).keys():
  File "/home/runner/TheDiscordMathProblemBot/problems_module.py", line 489, in get_guild_problems
    self.update_cache()
  File "/home/runner/TheDiscordMathProblemBot/problems_module.py", line 459, in update_cache
    problem = MathProblem.from_dict(self._sqldict[key])
AttributeError: 'MathProblemCache' object has no attribute '_sqldict'


Mon Oct 25 00:58:21 2021

Traceback (most recent call last):
  File "/opt/virtualenvs/python3/lib/python3.8/site-packages/dislash/application_commands/slash_client.py", line 1282, in _on_slash_command
    await app_command.invoke(inter)
  File "/opt/virtualenvs/python3/lib/python3.8/site-packages/dislash/application_commands/slash_core.py", line 216, in invoke
    raise err
  File "/opt/virtualenvs/python3/lib/python3.8/site-packages/dislash/application_commands/slash_core.py", line 212, in invoke
    await self._maybe_cog_call(self._cog, interaction, interaction.data)
  File "/opt/virtualenvs/python3/lib/python3.8/site-packages/dislash/application_commands/slash_core.py", line 37, in _maybe_cog_call
    return await self(inter, **params)
  File "/opt/virtualenvs/python3/lib/python3.8/site-packages/dislash/application_commands/core.py", line 72, in __call__
    return await self.func(*args, **kwargs)
  File "main.py", line 351, in submit_problem
    if ctx.guild != None and ctx.guild.id not in main_cache.get_guilds():
  File "/home/runner/TheDiscordMathProblemBot/problems_module.py", line 603, in get_guilds
    self.update_cache()
  File "/home/runner/TheDiscordMathProblemBot/problems_module.py", line 460, in update_cache
    guild_problems[p[0]][problem.id] = Problem #Convert it to a math problem
NameError: name 'Problem' is not defined


Mon Oct 25 00:58:40 2021

Traceback (most recent call last):
  File "/opt/virtualenvs/python3/lib/python3.8/site-packages/dislash/application_commands/slash_client.py", line 1282, in _on_slash_command
    await app_command.invoke(inter)
  File "/opt/virtualenvs/python3/lib/python3.8/site-packages/dislash/application_commands/slash_core.py", line 216, in invoke
    raise err
  File "/opt/virtualenvs/python3/lib/python3.8/site-packages/dislash/application_commands/slash_core.py", line 212, in invoke
    await self._maybe_cog_call(self._cog, interaction, interaction.data)
  File "/opt/virtualenvs/python3/lib/python3.8/site-packages/dislash/application_commands/slash_core.py", line 37, in _maybe_cog_call
    return await self(inter, **params)
  File "/opt/virtualenvs/python3/lib/python3.8/site-packages/dislash/application_commands/core.py", line 72, in __call__
    return await self.func(*args, **kwargs)
  File "main.py", line 409, in submit_problem
    if problem_id not in [problem.id for problem in main_cache.get_global_problems()]:
  File "main.py", line 409, in <listcomp>
    if problem_id not in [problem.id for problem in main_cache.get_global_problems()]:
AttributeError: 'int' object has no attribute 'id'


Mon Oct 25 01:01:15 2021

Traceback (most recent call last):
  File "/opt/virtualenvs/python3/lib/python3.8/site-packages/dislash/application_commands/slash_client.py", line 1282, in _on_slash_command
    await app_command.invoke(inter)
  File "/opt/virtualenvs/python3/lib/python3.8/site-packages/dislash/application_commands/slash_core.py", line 216, in invoke
    raise err
  File "/opt/virtualenvs/python3/lib/python3.8/site-packages/dislash/application_commands/slash_core.py", line 212, in invoke
    await self._maybe_cog_call(self._cog, interaction, interaction.data)
  File "/opt/virtualenvs/python3/lib/python3.8/site-packages/dislash/application_commands/slash_core.py", line 37, in _maybe_cog_call
    return await self(inter, **params)
  File "/opt/virtualenvs/python3/lib/python3.8/site-packages/dislash/application_commands/core.py", line 72, in __call__
    return await self.func(*args, **kwargs)
  File "main.py", line 410, in submit_problem
    if problem_id not in [problem.id for problem in main_cache.get_global_problems()]:
  File "main.py", line 410, in <listcomp>
    if problem_id not in [problem.id for problem in main_cache.get_global_problems()]:
AttributeError: 'int' object has no attribute 'id'


