Sat Sep 18 22:37:41 2021

Sat Sep 18 22:38:15 2021

Traceback (most recent call last):
  File "/opt/virtualenvs/python3/lib/python3.8/site-packages/dislash/application_commands/slash_client.py", line 1282, in _on_slash_command
    await app_command.invoke(inter)
  File "/opt/virtualenvs/python3/lib/python3.8/site-packages/dislash/application_commands/slash_core.py", line 216, in invoke
    raise err
  File "/opt/virtualenvs/python3/lib/python3.8/site-packages/dislash/application_commands/slash_core.py", line 212, in invoke
    await self._maybe_cog_call(self._cog, interaction, interaction.data)
  File "/opt/virtualenvs/python3/lib/python3.8/site-packages/dislash/application_commands/slash_core.py", line 37, in _maybe_cog_call
    return await self(inter, **params)
  File "/opt/virtualenvs/python3/lib/python3.8/site-packages/dislash/application_commands/core.py", line 72, in __call__
    return await self.func(*args, **kwargs)
  File "main.py", line 625, in raise_error
    raise error
Exception: Manually raised error by <@844633345815871519>


Sat Sep 18 22:40:17 2021

Traceback (most recent call last):
  File "/opt/virtualenvs/python3/lib/python3.8/site-packages/dislash/application_commands/slash_client.py", line 1282, in _on_slash_command
    await app_command.invoke(inter)
  File "/opt/virtualenvs/python3/lib/python3.8/site-packages/dislash/application_commands/slash_core.py", line 216, in invoke
    raise err
  File "/opt/virtualenvs/python3/lib/python3.8/site-packages/dislash/application_commands/slash_core.py", line 212, in invoke
    await self._maybe_cog_call(self._cog, interaction, interaction.data)
  File "/opt/virtualenvs/python3/lib/python3.8/site-packages/dislash/application_commands/slash_core.py", line 37, in _maybe_cog_call
    return await self(inter, **params)
  File "/opt/virtualenvs/python3/lib/python3.8/site-packages/dislash/application_commands/core.py", line 72, in __call__
    return await self.func(*args, **kwargs)
  File "main.py", line 625, in raise_error
    raise error
Exception: Manually raised error by <@844633345815871519>


Sat Sep 18 22:40:26 2021

Traceback (most recent call last):
  File "/opt/virtualenvs/python3/lib/python3.8/site-packages/dislash/application_commands/slash_client.py", line 1282, in _on_slash_command
    await app_command.invoke(inter)
  File "/opt/virtualenvs/python3/lib/python3.8/site-packages/dislash/application_commands/slash_core.py", line 216, in invoke
    raise err
  File "/opt/virtualenvs/python3/lib/python3.8/site-packages/dislash/application_commands/slash_core.py", line 212, in invoke
    await self._maybe_cog_call(self._cog, interaction, interaction.data)
  File "/opt/virtualenvs/python3/lib/python3.8/site-packages/dislash/application_commands/slash_core.py", line 37, in _maybe_cog_call
    return await self(inter, **params)
  File "/opt/virtualenvs/python3/lib/python3.8/site-packages/dislash/application_commands/core.py", line 72, in __call__
    return await self.func(*args, **kwargs)
  File "main.py", line 625, in raise_error
    raise error
Exception: Manually raised error by <@844633345815871519>


Sun Sep 19 20:11:48 2021

Traceback (most recent call last):
  File "/home/runner/TheDiscordMathProblemBot/problems_module.py", line 217, in get_problem
    return guild_id_dict[problem_id]
KeyError: '85314841192390'

During handling of the above exception, another exception occurred:

Traceback (most recent call last):
  File "/opt/virtualenvs/python3/lib/python3.8/site-packages/dislash/application_commands/slash_client.py", line 1282, in _on_slash_command
    await app_command.invoke(inter)
  File "/opt/virtualenvs/python3/lib/python3.8/site-packages/dislash/application_commands/slash_core.py", line 216, in invoke
    raise err
  File "/opt/virtualenvs/python3/lib/python3.8/site-packages/dislash/application_commands/slash_core.py", line 212, in invoke
    await self._maybe_cog_call(self._cog, interaction, interaction.data)
  File "/opt/virtualenvs/python3/lib/python3.8/site-packages/dislash/application_commands/slash_core.py", line 37, in _maybe_cog_call
    return await self(inter, **params)
  File "/opt/virtualenvs/python3/lib/python3.8/site-packages/dislash/application_commands/core.py", line 72, in __call__
    return await self.func(*args, **kwargs)
  File "main.py", line 240, in show_problem_info
    guildMathProblems[guild_id]={}
  File "/home/runner/TheDiscordMathProblemBot/problems_module.py", line 219, in get_problem
    raise Exception("*** Problem not found. Aborting search... ***")
Exception: *** Problem not found. Aborting search... ***


